{
  "xsize": 16,
  "zsize": 16,
  "slices": [
    [
      "  ccccdkaaaaand ",
      "  c___gkaaaaan_ ",
      "  ccc_hkaaaaan_ ",
      "  dddghkaaaaan_ ",
      "  eeeeelaaaaan_ ",
      "  aaaaaaaaaaan_ ",
      "  aaaaaaaaaaan_ ",
      "  aaaaaaaaaaan_ ",
      "  aaaaaaaaaaan_ ",
      "  aaaaaaaaaaan_ ",
      "  fffffmaaaaan_ ",
      "  d___ikaaaaan_ ",
      "  c___jkaaaaan_ ",
      "  c___hkaaaaan_ ",
      "  c___gkaaaaan_ ",
      "  ccccdkaaaaand "
    ],
    [
      "  cccckvpDGDpyn ",
      "  c___kv_DGDpyn ",
      "  ccc_kv_FGDpyn ",
      "  eeeerw_FGDpyn ",
      "  oooos_FDGDpyn ",
      "  pp___F_DGDpyn ",
      "  D__FF__DGDpyn ",
      "  EFF____DGDpyn ",
      "  D__FF__DGDpyn ",
      "  pp___F_DGDpyn ",
      "  qqqqt_FDGDpyn ",
      "  ffffux_DGDpyn ",
      "  c___kv_FGDpyn ",
      "  c___kv_DGDpyn ",
      "  c___kvpDGDpyn ",
      "  cccckvpDGDpyn "
    ],
    [
      "  ccccb_______b ",
      "  c___b_______b ",
      "  ccc_b_______b ",
      "  bbbb________b ",
      "  ____________b ",
      "  ____________b ",
      "  ____________b ",
      "  ____________b ",
      "  ____________b ",
      "  ____________b ",
      "  ____________b ",
      "  bbbb________b ",
      "  c___b_______b ",
      "  c___b_______b ",
      "  c___b_______b ",
      "  ccccb_______b "
    ],
    [
      "  ccccb_______b ",
      "  c___b_______b ",
      "  ccc_b_______b ",
      "  bbbb________b ",
      "  ____________b ",
      "  ____________b ",
      "  ____________b ",
      "  ____________b ",
      "  ____________b ",
      "  ____________b ",
      "  ____________b ",
      "  bbbb________b ",
      "  c___b_______b ",
      "  c___b_______b ",
      "  c___b_______b ",
      "  ccccb_______b "
    ],
    [
      "  ccccb_______b ",
      "  c___b_______b ",
      "  ccc_b_______b ",
      "  bbbb________b ",
      "  ____________b ",
      "  ____________b ",
      "  ____________b ",
      "  ____________b ",
      "  ____________b ",
      "  ____________b ",
      "  ____________b ",
      "  bbbb________b ",
      "  c___b_______b ",
      "  c___b_______b ",
      "  c___b_______b ",
      "  ccccb_______b "
    ],
    [
      "  ccccb_______b ",
      "  c___b_______b ",
      "  ccc_b_______b ",
      "  bbbb________b ",
      "  ____________b ",
      "  ____________b ",
      "  ____________b ",
      "  ____________b ",
      "  ____________b ",
      "  ____________b ",
      "  ____________b ",
      "  bbbb________b ",
      "  c___b_______b ",
      "  c___b_______b ",
      "  c___b_______b ",
      "  ccccb_______b "
    ],
    [
      "  ccccb_______b ",
      "  c___b_______b ",
      "  ccc_b_______b ",
      "  bbbb________b ",
      "  ____________b ",
      "  ____________b ",
      "  ____________b ",
      "  ____________b ",
      "  ____________b ",
      "  ____________b ",
      "  ____________b ",
      "  bbbb________b ",
      "  c___b_______b ",
      "  c___b_______b ",
      "  c___b_______b ",
      "  ccccb_______b "
    ],
    [
      "  ccccbJ_____Kb ",
      "  c___bJ_____Kb ",
      "  cdg_bJ_____Kb ",
      "  bbbbb______Kb ",
      "  HHHH_______Kb ",
      "  ___________Kb ",
      "  ___________Kb ",
      "  ___________Kb ",
      "  ___________Kb ",
      "  ___________Kb ",
      "  IIII_______Kb ",
      "  bbbbb______Kb ",
      "  c___bJ_____Kb ",
      "  c___bJ_____Kb ",
      "  c___bJ_____Kb ",
      "  ccccbJ_____Kb "
    ],
    [
      "  ccccybHHHHHbv ",
      "  c___yb_____bv ",
      "  c___yb_____bv ",
      "  qqqqzb_____bv ",
      "  bbbbbb_____bv ",
      "  J__________bv ",
      "  J__________bv ",
      "  J__________bv ",
      "  J__________bv ",
      "  J__________bv ",
      "  bbbbbb_____bv ",
      "  ooooAb_____bv ",
      "  c___yb_____bv ",
      "  c___yb_____bv ",
      "  c___yb_____bv ",
      "  ccccybIIIIIbv "
    ],
    [
      "  cccccybbbbbvc ",
      "  c____ybbbbbv_ ",
      "  c____ybbbbbv_ ",
      "  c____ybbbbbv_ ",
      "  qqqqqBbbbbbv_ ",
      "  bbbbbbbbbbbv_ ",
      "  bbbbbbbbbbbv_ ",
      "  bbbbbbbbbbbv_ ",
      "  bbbbbbbbbbbv_ ",
      "  bbbbbbbbbbbv_ ",
      "  oooooCbbbbbv_ ",
      "  c____ybbbbbv_ ",
      "  c____ybbbbbv_ ",
      "  c____ybbbbbv_ ",
      "  c____ybbbbbv_ ",
      "  cccccybbbbbvc "
    ]
  ],
  "palette": {
    "palette": [
      {
        "char": "_",
        "block": "minecraft:air"
      },
      {
        "char": "a",
        "block": "create:cut_deepslate_bricks"
      },
      {
        "char": "b",
        "block": "create:layered_deepslate"
      },
      {
        "char": "c",
        "block": "minecraft:water[level=8]"
      },
      {
        "char": "d",
        "block": "minecraft:water[level=1]"
      },
      {
        "char": "e",
        "block": "create:cut_deepslate_brick_stairs[half=top,waterlogged=false,shape=straight,facing=south]"
      },
      {
        "char": "f",
        "block": "create:cut_deepslate_brick_stairs[half=top,waterlogged=false,shape=straight,facing=north]"
      },
      {
        "char": "g",
        "block": "minecraft:water[level=2]"
      },
      {
        "char": "h",
        "block": "minecraft:water[level=3]"
      },
      {
        "char": "i",
        "block": "minecraft:water[level=5]"
      },
      {
        "char": "j",
        "block": "minecraft:water[level=4]"
      },
      {
        "char": "k",
        "block": "create:cut_deepslate_brick_stairs[half=top,waterlogged=false,shape=straight,facing=east]"
      },
      {
        "char": "l",
        "block": "create:cut_deepslate_brick_stairs[half=top,waterlogged=false,shape=inner_right,facing=east]"
      },
      {
        "char": "m",
        "block": "create:cut_deepslate_brick_stairs[half=top,waterlogged=false,shape=inner_left,facing=east]"
      },
      {
        "char": "n",
        "block": "create:cut_deepslate_brick_stairs[half=top,waterlogged=false,shape=straight,facing=west]"
      },
      {
        "char": "o",
        "block": "create:cut_deepslate_brick_stairs[half=bottom,waterlogged=false,shape=straight,facing=north]"
      },
      {
        "char": "p",
        "block": "create:cut_deepslate_brick_slab[waterlogged=false,type=bottom]"
      },
      {
        "char": "q",
        "block": "create:cut_deepslate_brick_stairs[half=bottom,waterlogged=false,shape=straight,facing=south]"
      },
      {
        "char": "r",
        "block": "create:cut_deepslate_brick_stairs[half=top,waterlogged=false,shape=outer_left,facing=west]"
      },
      {
        "char": "s",
        "block": "create:cut_deepslate_brick_stairs[half=bottom,waterlogged=false,shape=outer_right,facing=west]"
      },
      {
        "char": "t",
        "block": "create:cut_deepslate_brick_stairs[half=bottom,waterlogged=false,shape=outer_left,facing=west]"
      },
      {
        "char": "u",
        "block": "create:cut_deepslate_brick_stairs[half=top,waterlogged=false,shape=outer_right,facing=west]"
      },
      {
        "char": "v",
        "block": "create:cut_deepslate_brick_stairs[half=bottom,waterlogged=false,shape=straight,facing=west]"
      },
      {
        "char": "w",
        "block": "create:cut_deepslate_brick_stairs[half=bottom,waterlogged=false,shape=outer_left,facing=north]"
      },
      {
        "char": "x",
        "block": "create:cut_deepslate_brick_stairs[half=bottom,waterlogged=false,shape=outer_right,facing=south]"
      },
      {
        "char": "y",
        "block": "create:cut_deepslate_brick_stairs[half=bottom,waterlogged=false,shape=straight,facing=east]"
      },
      {
        "char": "z",
        "block": "create:cut_deepslate_brick_stairs[half=bottom,waterlogged=false,shape=inner_right,facing=east]"
      },
      {
        "char": "A",
        "block": "create:cut_deepslate_brick_stairs[half=bottom,waterlogged=false,shape=inner_left,facing=east]"
      },
      {
        "char": "B",
        "block": "create:cut_deepslate_brick_stairs[half=bottom,waterlogged=false,shape=inner_left,facing=south]"
      },
      {
        "char": "C",
        "block": "create:cut_deepslate_brick_stairs[half=bottom,waterlogged=false,shape=inner_right,facing=north]"
      },
      {
        "char": "D",
        "block": "railways:casing_collision[waterlogged=false]"
      },
      {
        "char": "E",
        "block": "create:track[waterlogged=false,shape=xo,turn=true]"
      },
      {
        "char": "F",
        "block": "create:fake_track[waterlogged=false]"
      },
      {
        "char": "G",
        "block": "create:track[waterlogged=false,shape=zo,turn=true]"
      },
      {
        "char": "H",
        "block": "create:cut_deepslate_bricks"
      },
      {
        "char": "I",
        "block": "create:cut_deepslate_bricks"
      },
      {
        "char": "J",
        "block": "create:cut_deepslate_bricks"
      },
      {
        "char": "K",
        "block": "create:cut_deepslate_bricks"
      }
    ]
  }
}