{
  "xsize": 16,
  "zsize": 16,
  "slices": [
    [
      "                ",
      "                ",
      "                ",
      "                ",
      "________________",
      "cccccccccccccccc",
      "aaaaaaaaaaaaaaaa",
      "aaaaaaaaaaaaaaaa",
      "aaaaaaaaaaaaaaaa",
      "aaaaaaaaaaaaaaaa",
      "aaaaaaaaaaaaaaaa",
      "dddddddddddddddd",
      "________________",
      "                ",
      "                ",
      "                "
    ],
    [
      "                ",
      "                ",
      "                ",
      "                ",
      "cccccccccccccccc",
      "eeeeeeeeeeeeeeee",
      "ffffffffffffffff",
      "________________",
      "gggggggggggggggg",
      "__i___i________i",
      "ffffffffffffffff",
      "hhhhhhhhhhhhhhhh",
      "dddddddddddddddd",
      "                ",
      "                ",
      "                "
    ],
    [
      "                ",
      "                ",
      "                ",
      "                ",
      "bbbbbbbbbbbbbbbb",
      "________________",
      "________________",
      "________________",
      "________________",
      "________________",
      "________________",
      "________________",
      "bbbbbbbbbbbbbbbb",
      "                ",
      "                ",
      "                "
    ],
    [
      "                ",
      "                ",
      "                ",
      "                ",
      "baaaaaaaaaaaaaab",
      "________________",
      "________________",
      "________________",
      "________________",
      "________________",
      "________________",
      "________________",
      "baaaaaaaaaaaaaab",
      "                ",
      "                ",
      "                "
    ],
    [
      "                ",
      "                ",
      "                ",
      "                ",
      "baaaaaaaaaaaaaab",
      "________________",
      "________________",
      "________________",
      "________________",
      "________________",
      "________________",
      "________________",
      "baaaaaaaaaaaaaab",
      "                ",
      "                ",
      "                "
    ],
    [
      "                ",
      "                ",
      "                ",
      "                ",
      "baaaaaaaaaaaaaab",
      "________________",
      "________________",
      "________________",
      "________________",
      "________________",
      "________________",
      "________________",
      "baaaaaaaaaaaaaab",
      "                ",
      "                ",
      "                "
    ],
    [
      "                ",
      "                ",
      "                ",
      "                ",
      "baaaaaaaaaaaaaab",
      "________________",
      "________________",
      "________________",
      "________________",
      "________________",
      "________________",
      "________________",
      "baaaaaaaaaaaaaab",
      "                ",
      "                ",
      "                "
    ],
    [
      "                ",
      "                ",
      "                ",
      "                ",
      "bbbbbbbbbbbbbbbb",
      "jjjjjjjjjjjjjjjj",
      "________________",
      "________________",
      "________________",
      "________________",
      "________________",
      "kkkkkkkkkkkkkkkk",
      "bbbbbbbbbbbbbbbb",
      "                ",
      "                ",
      "                "
    ],
    [
      "                ",
      "                ",
      "                ",
      "                ",
      "hhhhhhhhhhhhhhhh",
      "bbbbbbbbbbbbbbbb",
      "l______________m",
      "l______________m",
      "l______________m",
      "l______________m",
      "l______________m",
      "bbbbbbbbbbbbbbbb",
      "eeeeeeeeeeeeeeee",
      "                ",
      "                ",
      "                "
    ],
    [
      "                ",
      "                ",
      "                ",
      "                ",
      "________________",
      "hhhhhhhhhhhhhhhh",
      "baaaaaaaaaaaaaab",
      "baaaaaaaaaaaaaab",
      "baaaaaaaaaaaaaab",
      "baaaaaaaaaaaaaab",
      "baaaaaaaaaaaaaab",
      "eeeeeeeeeeeeeeee",
      "________________",
      "                ",
      "                ",
      "                "
    ]
  ],
  "palette": {
    "palette": [
      {
        "char": "_",
        "block": "minecraft:air"
      },
      {
        "char": "a",
        "block": "create:cut_deepslate_bricks"
      },
      {
        "char": "b",
        "block": "create:layered_deepslate"
      },
      {
        "char": "c",
        "block": "create:cut_deepslate_brick_stairs[half=top,waterlogged=false,shape=straight,facing=south]"
      },
      {
        "char": "d",
        "block": "create:cut_deepslate_brick_stairs[half=top,waterlogged=false,shape=straight,facing=north]"
      },
      {
        "char": "e",
        "block": "create:cut_deepslate_brick_stairs[half=bottom,waterlogged=false,shape=straight,facing=north]"
      },
      {
        "char": "f",
        "block": "create:cut_deepslate_brick_slab[waterlogged=false,type=bottom]"
      },
      {
        "char": "g",
        "block": "create:track[waterlogged=false,shape=xo,turn=false]"
      },
      {
        "char": "h",
        "block": "create:cut_deepslate_brick_stairs[half=bottom,waterlogged=false,shape=straight,facing=south]"
      },
      {
        "char": "i",
        "block": "railways:casing_collision[waterlogged=false]"
      },
      {
        "char": "j",
        "block": "create:cut_deepslate_bricks"
      },
      {
        "char": "k",
        "block": "create:cut_deepslate_bricks"
      },
      {
        "char": "l",
        "block": "create:cut_deepslate_bricks"
      },
      {
        "char": "m",
        "block": "create:cut_deepslate_bricks"
      }
    ]
  }
}